[2020-06-21 20:16:42,253 INFO] [in E:\GitWorkplace\hting\utils\loggings.py:77]
this is root_logger logging: app.logger is True, configuring app_logger.......
[2020-06-21 20:16:42,253 WARNING] [in E:\GitWorkplace\hting\application.py:23]
启动生产模式
[2020-06-21 20:16:42,253 WARNING] [in E:\GitWorkplace\hting\application.py:23]
启动生产模式
[2020-06-21 20:16:42,364 INFO] [in E:\python\venv\hting\lib\site-packages\werkzeug\_internal.py:113]
 * Running on http://127.0.0.1:5000/ (Press CTRL+C to quit)
[2020-06-21 20:25:37,966 INFO] [in E:\GitWorkplace\hting\utils\loggings.py:77]
this is root_logger logging: app.logger is True, configuring app_logger.......
[2020-06-21 20:25:37,966 WARNING] [in E:\GitWorkplace\hting\application.py:23]
启动生产模式
[2020-06-21 20:25:37,966 WARNING] [in E:\GitWorkplace\hting\application.py:23]
启动生产模式
[2020-06-21 20:25:37,977 INFO] [in E:\python\venv\hting\lib\site-packages\werkzeug\_internal.py:113]
 * Running on http://127.0.0.1:5000/ (Press CTRL+C to quit)
[2020-06-21 20:29:40,482 INFO] [in E:\GitWorkplace\hting\utils\loggings.py:77]
this is root_logger logging: app.logger is True, configuring app_logger.......
[2020-06-21 20:29:40,483 WARNING] [in E:\GitWorkplace\hting\application.py:23]
启动生产模式
[2020-06-21 20:29:40,483 WARNING] [in E:\GitWorkplace\hting\application.py:23]
启动生产模式
[2020-06-21 20:29:40,493 INFO] [in E:\python\venv\hting\lib\site-packages\werkzeug\_internal.py:113]
 * Running on http://127.0.0.1:5000/ (Press CTRL+C to quit)
[2020-06-21 20:31:44,029 INFO] [in E:\GitWorkplace\hting\utils\loggings.py:77]
this is root_logger logging: app.logger is True, configuring app_logger.......
[2020-06-21 20:31:44,030 WARNING] [in E:\GitWorkplace\hting\application.py:23]
启动生产模式
[2020-06-21 20:31:44,030 WARNING] [in E:\GitWorkplace\hting\application.py:23]
启动生产模式
[2020-06-21 20:31:44,046 INFO] [in E:\python\venv\hting\lib\site-packages\werkzeug\_internal.py:113]
 * Running on http://127.0.0.1:5000/ (Press CTRL+C to quit)
[2020-06-21 20:33:01,260 INFO] [in E:\GitWorkplace\hting\utils\loggings.py:77]
this is root_logger logging: app.logger is True, configuring app_logger.......
[2020-06-21 20:33:01,260 WARNING] [in E:\GitWorkplace\hting\application.py:23]
启动生产模式
[2020-06-21 20:33:01,260 WARNING] [in E:\GitWorkplace\hting\application.py:23]
启动生产模式
[2020-06-21 20:33:01,274 INFO] [in E:\python\venv\hting\lib\site-packages\werkzeug\_internal.py:113]
 * Running on http://127.0.0.1:5000/ (Press CTRL+C to quit)
[2020-06-21 20:39:32,066 INFO] [in E:\GitWorkplace\hting\utils\loggings.py:77]
this is root_logger logging: app.logger is True, configuring app_logger.......
[2020-06-21 20:39:32,066 WARNING] [in E:\GitWorkplace\hting\application.py:23]
启动生产模式
[2020-06-21 20:39:32,066 WARNING] [in E:\GitWorkplace\hting\application.py:23]
启动生产模式
[2020-06-21 20:39:32,076 INFO] [in E:\python\venv\hting\lib\site-packages\werkzeug\_internal.py:113]
 * Running on http://127.0.0.1:5000/ (Press CTRL+C to quit)
[2020-06-21 20:40:28,959 INFO] [in E:\GitWorkplace\hting\utils\loggings.py:77]
this is root_logger logging: app.logger is True, configuring app_logger.......
[2020-06-21 20:40:28,959 WARNING] [in E:\GitWorkplace\hting\application.py:23]
启动生产模式
[2020-06-21 20:40:28,959 WARNING] [in E:\GitWorkplace\hting\application.py:23]
启动生产模式
[2020-06-21 20:40:28,972 INFO] [in E:\python\venv\hting\lib\site-packages\werkzeug\_internal.py:113]
 * Running on http://127.0.0.1:5000/ (Press CTRL+C to quit)
[2020-06-21 20:41:57,470 INFO] [in E:\GitWorkplace\hting\utils\loggings.py:77]
this is root_logger logging: app.logger is True, configuring app_logger.......
[2020-06-21 20:41:57,470 WARNING] [in E:\GitWorkplace\hting\application.py:23]
启动生产模式
[2020-06-21 20:41:57,470 WARNING] [in E:\GitWorkplace\hting\application.py:23]
启动生产模式
[2020-06-21 20:41:57,485 INFO] [in E:\python\venv\hting\lib\site-packages\werkzeug\_internal.py:113]
 * Running on http://127.0.0.1:5000/ (Press CTRL+C to quit)
[2020-06-21 21:07:03,609 INFO] [in E:\GitWorkplace\hting\utils\loggings.py:77]
this is root_logger logging: app.logger is True, configuring app_logger.......
[2020-06-21 21:07:03,610 WARNING] [in E:\GitWorkplace\hting\application.py:23]
启动生产模式
[2020-06-21 21:07:03,610 WARNING] [in E:\GitWorkplace\hting\application.py:23]
启动生产模式
[2020-06-21 21:07:03,625 INFO] [in E:\python\venv\hting\lib\site-packages\werkzeug\_internal.py:113]
 * Running on http://127.0.0.1:5000/ (Press CTRL+C to quit)
[2020-06-21 21:07:38,699 ERROR] [in E:\python\venv\hting\lib\site-packages\flask\app.py:1891]
Exception on / [GET]
Traceback (most recent call last):
  File "E:\python\venv\hting\lib\site-packages\flask\app.py", line 1950, in full_dispatch_request
    rv = self.dispatch_request()
  File "E:\python\venv\hting\lib\site-packages\flask\app.py", line 1926, in dispatch_request
    self.raise_routing_exception(req)
  File "E:\python\venv\hting\lib\site-packages\flask\app.py", line 1908, in raise_routing_exception
    raise request.routing_exception
  File "E:\python\venv\hting\lib\site-packages\flask\ctx.py", line 350, in match_request
    result = self.url_adapter.match(return_rule=True)
  File "E:\python\venv\hting\lib\site-packages\werkzeug\routing.py", line 1945, in match
    raise NotFound()
werkzeug.exceptions.NotFound: 404 Not Found: The requested URL was not found on the server. If you entered the URL manually please check your spelling and try again.

During handling of the above exception, another exception occurred:

Traceback (most recent call last):
  File "E:\python\venv\hting\lib\site-packages\flask\app.py", line 2447, in wsgi_app
    response = self.full_dispatch_request()
  File "E:\python\venv\hting\lib\site-packages\flask\app.py", line 1952, in full_dispatch_request
    rv = self.handle_user_exception(e)
  File "E:\python\venv\hting\lib\site-packages\flask\app.py", line 1816, in handle_user_exception
    return self.handle_http_exception(e)
  File "E:\python\venv\hting\lib\site-packages\flask\app.py", line 1744, in handle_http_exception
    return handler(e)
  File "E:\GitWorkplace\hting\application.py", line 31, in page_not_found
    return render_template("error/404.html"), 404
  File "E:\python\venv\hting\lib\site-packages\flask\templating.py", line 138, in render_template
    ctx.app.jinja_env.get_or_select_template(template_name_or_list),
  File "E:\python\venv\hting\lib\site-packages\jinja2\environment.py", line 930, in get_or_select_template
    return self.get_template(template_name_or_list, parent, globals)
  File "E:\python\venv\hting\lib\site-packages\jinja2\environment.py", line 883, in get_template
    return self._load_template(name, self.make_globals(globals))
  File "E:\python\venv\hting\lib\site-packages\jinja2\environment.py", line 857, in _load_template
    template = self.loader.load(self, name, globals)
  File "E:\python\venv\hting\lib\site-packages\jinja2\loaders.py", line 115, in load
    source, filename, uptodate = self.get_source(environment, name)
  File "E:\python\venv\hting\lib\site-packages\flask\templating.py", line 60, in get_source
    return self._get_source_fast(environment, template)
  File "E:\python\venv\hting\lib\site-packages\flask\templating.py", line 89, in _get_source_fast
    raise TemplateNotFound(template)
jinja2.exceptions.TemplateNotFound: error/404.html
[2020-06-21 21:07:38,699 ERROR] [in E:\python\venv\hting\lib\site-packages\flask\app.py:1891]
Exception on / [GET]
Traceback (most recent call last):
  File "E:\python\venv\hting\lib\site-packages\flask\app.py", line 1950, in full_dispatch_request
    rv = self.dispatch_request()
  File "E:\python\venv\hting\lib\site-packages\flask\app.py", line 1926, in dispatch_request
    self.raise_routing_exception(req)
  File "E:\python\venv\hting\lib\site-packages\flask\app.py", line 1908, in raise_routing_exception
    raise request.routing_exception
  File "E:\python\venv\hting\lib\site-packages\flask\ctx.py", line 350, in match_request
    result = self.url_adapter.match(return_rule=True)
  File "E:\python\venv\hting\lib\site-packages\werkzeug\routing.py", line 1945, in match
    raise NotFound()
werkzeug.exceptions.NotFound: 404 Not Found: The requested URL was not found on the server. If you entered the URL manually please check your spelling and try again.

During handling of the above exception, another exception occurred:

Traceback (most recent call last):
  File "E:\python\venv\hting\lib\site-packages\flask\app.py", line 2447, in wsgi_app
    response = self.full_dispatch_request()
  File "E:\python\venv\hting\lib\site-packages\flask\app.py", line 1952, in full_dispatch_request
    rv = self.handle_user_exception(e)
  File "E:\python\venv\hting\lib\site-packages\flask\app.py", line 1816, in handle_user_exception
    return self.handle_http_exception(e)
  File "E:\python\venv\hting\lib\site-packages\flask\app.py", line 1744, in handle_http_exception
    return handler(e)
  File "E:\GitWorkplace\hting\application.py", line 31, in page_not_found
    return render_template("error/404.html"), 404
  File "E:\python\venv\hting\lib\site-packages\flask\templating.py", line 138, in render_template
    ctx.app.jinja_env.get_or_select_template(template_name_or_list),
  File "E:\python\venv\hting\lib\site-packages\jinja2\environment.py", line 930, in get_or_select_template
    return self.get_template(template_name_or_list, parent, globals)
  File "E:\python\venv\hting\lib\site-packages\jinja2\environment.py", line 883, in get_template
    return self._load_template(name, self.make_globals(globals))
  File "E:\python\venv\hting\lib\site-packages\jinja2\environment.py", line 857, in _load_template
    template = self.loader.load(self, name, globals)
  File "E:\python\venv\hting\lib\site-packages\jinja2\loaders.py", line 115, in load
    source, filename, uptodate = self.get_source(environment, name)
  File "E:\python\venv\hting\lib\site-packages\flask\templating.py", line 60, in get_source
    return self._get_source_fast(environment, template)
  File "E:\python\venv\hting\lib\site-packages\flask\templating.py", line 89, in _get_source_fast
    raise TemplateNotFound(template)
jinja2.exceptions.TemplateNotFound: error/404.html
[2020-06-21 21:07:38,961 ERROR] [in E:\GitWorkplace\hting\application.py:46]
Traceback (most recent call last):
  File "E:\python\venv\hting\lib\site-packages\flask\app.py", line 1950, in full_dispatch_request
    rv = self.dispatch_request()
  File "E:\python\venv\hting\lib\site-packages\flask\app.py", line 1926, in dispatch_request
    self.raise_routing_exception(req)
  File "E:\python\venv\hting\lib\site-packages\flask\app.py", line 1908, in raise_routing_exception
    raise request.routing_exception
  File "E:\python\venv\hting\lib\site-packages\flask\ctx.py", line 350, in match_request
    result = self.url_adapter.match(return_rule=True)
  File "E:\python\venv\hting\lib\site-packages\werkzeug\routing.py", line 1945, in match
    raise NotFound()
werkzeug.exceptions.NotFound: 404 Not Found: The requested URL was not found on the server. If you entered the URL manually please check your spelling and try again.

During handling of the above exception, another exception occurred:

Traceback (most recent call last):
  File "E:\python\venv\hting\lib\site-packages\flask\app.py", line 2447, in wsgi_app
    response = self.full_dispatch_request()
  File "E:\python\venv\hting\lib\site-packages\flask\app.py", line 1952, in full_dispatch_request
    rv = self.handle_user_exception(e)
  File "E:\python\venv\hting\lib\site-packages\flask\app.py", line 1816, in handle_user_exception
    return self.handle_http_exception(e)
  File "E:\python\venv\hting\lib\site-packages\flask\app.py", line 1744, in handle_http_exception
    return handler(e)
  File "E:\GitWorkplace\hting\application.py", line 31, in page_not_found
    return render_template("error/404.html"), 404
  File "E:\python\venv\hting\lib\site-packages\flask\templating.py", line 138, in render_template
    ctx.app.jinja_env.get_or_select_template(template_name_or_list),
  File "E:\python\venv\hting\lib\site-packages\jinja2\environment.py", line 930, in get_or_select_template
    return self.get_template(template_name_or_list, parent, globals)
  File "E:\python\venv\hting\lib\site-packages\jinja2\environment.py", line 883, in get_template
    return self._load_template(name, self.make_globals(globals))
  File "E:\python\venv\hting\lib\site-packages\jinja2\environment.py", line 857, in _load_template
    template = self.loader.load(self, name, globals)
  File "E:\python\venv\hting\lib\site-packages\jinja2\loaders.py", line 115, in load
    source, filename, uptodate = self.get_source(environment, name)
  File "E:\python\venv\hting\lib\site-packages\flask\templating.py", line 60, in get_source
    return self._get_source_fast(environment, template)
  File "E:\python\venv\hting\lib\site-packages\flask\templating.py", line 89, in _get_source_fast
    raise TemplateNotFound(template)
jinja2.exceptions.TemplateNotFound: error/404.html

[2020-06-21 21:07:38,961 ERROR] [in E:\GitWorkplace\hting\application.py:46]
Traceback (most recent call last):
  File "E:\python\venv\hting\lib\site-packages\flask\app.py", line 1950, in full_dispatch_request
    rv = self.dispatch_request()
  File "E:\python\venv\hting\lib\site-packages\flask\app.py", line 1926, in dispatch_request
    self.raise_routing_exception(req)
  File "E:\python\venv\hting\lib\site-packages\flask\app.py", line 1908, in raise_routing_exception
    raise request.routing_exception
  File "E:\python\venv\hting\lib\site-packages\flask\ctx.py", line 350, in match_request
    result = self.url_adapter.match(return_rule=True)
  File "E:\python\venv\hting\lib\site-packages\werkzeug\routing.py", line 1945, in match
    raise NotFound()
werkzeug.exceptions.NotFound: 404 Not Found: The requested URL was not found on the server. If you entered the URL manually please check your spelling and try again.

During handling of the above exception, another exception occurred:

Traceback (most recent call last):
  File "E:\python\venv\hting\lib\site-packages\flask\app.py", line 2447, in wsgi_app
    response = self.full_dispatch_request()
  File "E:\python\venv\hting\lib\site-packages\flask\app.py", line 1952, in full_dispatch_request
    rv = self.handle_user_exception(e)
  File "E:\python\venv\hting\lib\site-packages\flask\app.py", line 1816, in handle_user_exception
    return self.handle_http_exception(e)
  File "E:\python\venv\hting\lib\site-packages\flask\app.py", line 1744, in handle_http_exception
    return handler(e)
  File "E:\GitWorkplace\hting\application.py", line 31, in page_not_found
    return render_template("error/404.html"), 404
  File "E:\python\venv\hting\lib\site-packages\flask\templating.py", line 138, in render_template
    ctx.app.jinja_env.get_or_select_template(template_name_or_list),
  File "E:\python\venv\hting\lib\site-packages\jinja2\environment.py", line 930, in get_or_select_template
    return self.get_template(template_name_or_list, parent, globals)
  File "E:\python\venv\hting\lib\site-packages\jinja2\environment.py", line 883, in get_template
    return self._load_template(name, self.make_globals(globals))
  File "E:\python\venv\hting\lib\site-packages\jinja2\environment.py", line 857, in _load_template
    template = self.loader.load(self, name, globals)
  File "E:\python\venv\hting\lib\site-packages\jinja2\loaders.py", line 115, in load
    source, filename, uptodate = self.get_source(environment, name)
  File "E:\python\venv\hting\lib\site-packages\flask\templating.py", line 60, in get_source
    return self._get_source_fast(environment, template)
  File "E:\python\venv\hting\lib\site-packages\flask\templating.py", line 89, in _get_source_fast
    raise TemplateNotFound(template)
jinja2.exceptions.TemplateNotFound: error/404.html

[2020-06-21 21:07:39,001 INFO] [in E:\python\venv\hting\lib\site-packages\werkzeug\_internal.py:113]
127.0.0.1 - - [21/Jun/2020 21:07:39] "[35m[1mGET / HTTP/1.1[0m" 500 -
[2020-06-21 21:07:39,055 ERROR] [in E:\python\venv\hting\lib\site-packages\werkzeug\_internal.py:113]
Error on request:
Traceback (most recent call last):
  File "E:\python\venv\hting\Lib\site-packages\flask\app.py", line 1950, in full_dispatch_request
    rv = self.dispatch_request()
  File "E:\python\venv\hting\Lib\site-packages\flask\app.py", line 1926, in dispatch_request
    self.raise_routing_exception(req)
  File "E:\python\venv\hting\Lib\site-packages\flask\app.py", line 1908, in raise_routing_exception
    raise request.routing_exception
  File "E:\python\venv\hting\Lib\site-packages\flask\ctx.py", line 350, in match_request
    result = self.url_adapter.match(return_rule=True)
  File "E:\python\venv\hting\Lib\site-packages\werkzeug\routing.py", line 1945, in match
    raise NotFound()
werkzeug.exceptions.NotFound: 404 Not Found: The requested URL was not found on the server. If you entered the URL manually please check your spelling and try again.

During handling of the above exception, another exception occurred:

Traceback (most recent call last):
  File "E:\python\venv\hting\Lib\site-packages\flask\app.py", line 2447, in wsgi_app
    response = self.full_dispatch_request()
  File "E:\python\venv\hting\Lib\site-packages\flask\app.py", line 1952, in full_dispatch_request
    rv = self.handle_user_exception(e)
  File "E:\python\venv\hting\Lib\site-packages\flask\app.py", line 1816, in handle_user_exception
    return self.handle_http_exception(e)
  File "E:\python\venv\hting\Lib\site-packages\flask\app.py", line 1744, in handle_http_exception
    return handler(e)
  File "E:\GitWorkplace\hting\application.py", line 31, in page_not_found
    return render_template("error/404.html"), 404
  File "E:\python\venv\hting\Lib\site-packages\flask\templating.py", line 138, in render_template
    ctx.app.jinja_env.get_or_select_template(template_name_or_list),
  File "E:\python\venv\hting\Lib\site-packages\jinja2\environment.py", line 930, in get_or_select_template
    return self.get_template(template_name_or_list, parent, globals)
  File "E:\python\venv\hting\Lib\site-packages\jinja2\environment.py", line 883, in get_template
    return self._load_template(name, self.make_globals(globals))
  File "E:\python\venv\hting\Lib\site-packages\jinja2\environment.py", line 857, in _load_template
    template = self.loader.load(self, name, globals)
  File "E:\python\venv\hting\Lib\site-packages\jinja2\loaders.py", line 115, in load
    source, filename, uptodate = self.get_source(environment, name)
  File "E:\python\venv\hting\Lib\site-packages\flask\templating.py", line 60, in get_source
    return self._get_source_fast(environment, template)
  File "E:\python\venv\hting\Lib\site-packages\flask\templating.py", line 89, in _get_source_fast
    raise TemplateNotFound(template)
jinja2.exceptions.TemplateNotFound: error/404.html

During handling of the above exception, another exception occurred:

Traceback (most recent call last):
  File "E:\python\venv\hting\Lib\site-packages\werkzeug\serving.py", line 323, in run_wsgi
    execute(self.server.app)
  File "E:\python\venv\hting\Lib\site-packages\werkzeug\serving.py", line 312, in execute
    application_iter = app(environ, start_response)
  File "E:\python\venv\hting\Lib\site-packages\flask\app.py", line 2464, in __call__
    return self.wsgi_app(environ, start_response)
  File "E:\python\venv\hting\Lib\site-packages\flask\app.py", line 2450, in wsgi_app
    response = self.handle_exception(e)
  File "E:\python\venv\hting\Lib\site-packages\flask\app.py", line 1879, in handle_exception
    server_error = handler(server_error)
  File "E:\GitWorkplace\hting\application.py", line 47, in error_handler
    return render_template("error/503.html"), code
  File "E:\python\venv\hting\Lib\site-packages\flask\templating.py", line 138, in render_template
    ctx.app.jinja_env.get_or_select_template(template_name_or_list),
  File "E:\python\venv\hting\Lib\site-packages\jinja2\environment.py", line 930, in get_or_select_template
    return self.get_template(template_name_or_list, parent, globals)
  File "E:\python\venv\hting\Lib\site-packages\jinja2\environment.py", line 883, in get_template
    return self._load_template(name, self.make_globals(globals))
  File "E:\python\venv\hting\Lib\site-packages\jinja2\environment.py", line 857, in _load_template
    template = self.loader.load(self, name, globals)
  File "E:\python\venv\hting\Lib\site-packages\jinja2\loaders.py", line 115, in load
    source, filename, uptodate = self.get_source(environment, name)
  File "E:\python\venv\hting\Lib\site-packages\flask\templating.py", line 60, in get_source
    return self._get_source_fast(environment, template)
  File "E:\python\venv\hting\Lib\site-packages\flask\templating.py", line 89, in _get_source_fast
    raise TemplateNotFound(template)
jinja2.exceptions.TemplateNotFound: error/503.html
[2020-06-21 21:07:39,073 ERROR] [in E:\python\venv\hting\lib\site-packages\flask\app.py:1891]
Exception on /favicon.ico [GET]
Traceback (most recent call last):
  File "E:\python\venv\hting\lib\site-packages\flask\app.py", line 1950, in full_dispatch_request
    rv = self.dispatch_request()
  File "E:\python\venv\hting\lib\site-packages\flask\app.py", line 1926, in dispatch_request
    self.raise_routing_exception(req)
  File "E:\python\venv\hting\lib\site-packages\flask\app.py", line 1908, in raise_routing_exception
    raise request.routing_exception
  File "E:\python\venv\hting\lib\site-packages\flask\ctx.py", line 350, in match_request
    result = self.url_adapter.match(return_rule=True)
  File "E:\python\venv\hting\lib\site-packages\werkzeug\routing.py", line 1945, in match
    raise NotFound()
werkzeug.exceptions.NotFound: 404 Not Found: The requested URL was not found on the server. If you entered the URL manually please check your spelling and try again.

During handling of the above exception, another exception occurred:

Traceback (most recent call last):
  File "E:\python\venv\hting\lib\site-packages\flask\app.py", line 2447, in wsgi_app
    response = self.full_dispatch_request()
  File "E:\python\venv\hting\lib\site-packages\flask\app.py", line 1952, in full_dispatch_request
    rv = self.handle_user_exception(e)
  File "E:\python\venv\hting\lib\site-packages\flask\app.py", line 1816, in handle_user_exception
    return self.handle_http_exception(e)
  File "E:\python\venv\hting\lib\site-packages\flask\app.py", line 1744, in handle_http_exception
    return handler(e)
  File "E:\GitWorkplace\hting\application.py", line 31, in page_not_found
    return render_template("error/404.html"), 404
  File "E:\python\venv\hting\lib\site-packages\flask\templating.py", line 138, in render_template
    ctx.app.jinja_env.get_or_select_template(template_name_or_list),
  File "E:\python\venv\hting\lib\site-packages\jinja2\environment.py", line 930, in get_or_select_template
    return self.get_template(template_name_or_list, parent, globals)
  File "E:\python\venv\hting\lib\site-packages\jinja2\environment.py", line 883, in get_template
    return self._load_template(name, self.make_globals(globals))
  File "E:\python\venv\hting\lib\site-packages\jinja2\environment.py", line 857, in _load_template
    template = self.loader.load(self, name, globals)
  File "E:\python\venv\hting\lib\site-packages\jinja2\loaders.py", line 115, in load
    source, filename, uptodate = self.get_source(environment, name)
  File "E:\python\venv\hting\lib\site-packages\flask\templating.py", line 60, in get_source
    return self._get_source_fast(environment, template)
  File "E:\python\venv\hting\lib\site-packages\flask\templating.py", line 89, in _get_source_fast
    raise TemplateNotFound(template)
jinja2.exceptions.TemplateNotFound: error/404.html
[2020-06-21 21:07:39,073 ERROR] [in E:\python\venv\hting\lib\site-packages\flask\app.py:1891]
Exception on /favicon.ico [GET]
Traceback (most recent call last):
  File "E:\python\venv\hting\lib\site-packages\flask\app.py", line 1950, in full_dispatch_request
    rv = self.dispatch_request()
  File "E:\python\venv\hting\lib\site-packages\flask\app.py", line 1926, in dispatch_request
    self.raise_routing_exception(req)
  File "E:\python\venv\hting\lib\site-packages\flask\app.py", line 1908, in raise_routing_exception
    raise request.routing_exception
  File "E:\python\venv\hting\lib\site-packages\flask\ctx.py", line 350, in match_request
    result = self.url_adapter.match(return_rule=True)
  File "E:\python\venv\hting\lib\site-packages\werkzeug\routing.py", line 1945, in match
    raise NotFound()
werkzeug.exceptions.NotFound: 404 Not Found: The requested URL was not found on the server. If you entered the URL manually please check your spelling and try again.

During handling of the above exception, another exception occurred:

Traceback (most recent call last):
  File "E:\python\venv\hting\lib\site-packages\flask\app.py", line 2447, in wsgi_app
    response = self.full_dispatch_request()
  File "E:\python\venv\hting\lib\site-packages\flask\app.py", line 1952, in full_dispatch_request
    rv = self.handle_user_exception(e)
  File "E:\python\venv\hting\lib\site-packages\flask\app.py", line 1816, in handle_user_exception
    return self.handle_http_exception(e)
  File "E:\python\venv\hting\lib\site-packages\flask\app.py", line 1744, in handle_http_exception
    return handler(e)
  File "E:\GitWorkplace\hting\application.py", line 31, in page_not_found
    return render_template("error/404.html"), 404
  File "E:\python\venv\hting\lib\site-packages\flask\templating.py", line 138, in render_template
    ctx.app.jinja_env.get_or_select_template(template_name_or_list),
  File "E:\python\venv\hting\lib\site-packages\jinja2\environment.py", line 930, in get_or_select_template
    return self.get_template(template_name_or_list, parent, globals)
  File "E:\python\venv\hting\lib\site-packages\jinja2\environment.py", line 883, in get_template
    return self._load_template(name, self.make_globals(globals))
  File "E:\python\venv\hting\lib\site-packages\jinja2\environment.py", line 857, in _load_template
    template = self.loader.load(self, name, globals)
  File "E:\python\venv\hting\lib\site-packages\jinja2\loaders.py", line 115, in load
    source, filename, uptodate = self.get_source(environment, name)
  File "E:\python\venv\hting\lib\site-packages\flask\templating.py", line 60, in get_source
    return self._get_source_fast(environment, template)
  File "E:\python\venv\hting\lib\site-packages\flask\templating.py", line 89, in _get_source_fast
    raise TemplateNotFound(template)
jinja2.exceptions.TemplateNotFound: error/404.html
[2020-06-21 21:07:39,080 ERROR] [in E:\GitWorkplace\hting\application.py:46]
Traceback (most recent call last):
  File "E:\python\venv\hting\lib\site-packages\flask\app.py", line 1950, in full_dispatch_request
    rv = self.dispatch_request()
  File "E:\python\venv\hting\lib\site-packages\flask\app.py", line 1926, in dispatch_request
    self.raise_routing_exception(req)
  File "E:\python\venv\hting\lib\site-packages\flask\app.py", line 1908, in raise_routing_exception
    raise request.routing_exception
  File "E:\python\venv\hting\lib\site-packages\flask\ctx.py", line 350, in match_request
    result = self.url_adapter.match(return_rule=True)
  File "E:\python\venv\hting\lib\site-packages\werkzeug\routing.py", line 1945, in match
    raise NotFound()
werkzeug.exceptions.NotFound: 404 Not Found: The requested URL was not found on the server. If you entered the URL manually please check your spelling and try again.

During handling of the above exception, another exception occurred:

Traceback (most recent call last):
  File "E:\python\venv\hting\lib\site-packages\flask\app.py", line 2447, in wsgi_app
    response = self.full_dispatch_request()
  File "E:\python\venv\hting\lib\site-packages\flask\app.py", line 1952, in full_dispatch_request
    rv = self.handle_user_exception(e)
  File "E:\python\venv\hting\lib\site-packages\flask\app.py", line 1816, in handle_user_exception
    return self.handle_http_exception(e)
  File "E:\python\venv\hting\lib\site-packages\flask\app.py", line 1744, in handle_http_exception
    return handler(e)
  File "E:\GitWorkplace\hting\application.py", line 31, in page_not_found
    return render_template("error/404.html"), 404
  File "E:\python\venv\hting\lib\site-packages\flask\templating.py", line 138, in render_template
    ctx.app.jinja_env.get_or_select_template(template_name_or_list),
  File "E:\python\venv\hting\lib\site-packages\jinja2\environment.py", line 930, in get_or_select_template
    return self.get_template(template_name_or_list, parent, globals)
  File "E:\python\venv\hting\lib\site-packages\jinja2\environment.py", line 883, in get_template
    return self._load_template(name, self.make_globals(globals))
  File "E:\python\venv\hting\lib\site-packages\jinja2\environment.py", line 857, in _load_template
    template = self.loader.load(self, name, globals)
  File "E:\python\venv\hting\lib\site-packages\jinja2\loaders.py", line 115, in load
    source, filename, uptodate = self.get_source(environment, name)
  File "E:\python\venv\hting\lib\site-packages\flask\templating.py", line 60, in get_source
    return self._get_source_fast(environment, template)
  File "E:\python\venv\hting\lib\site-packages\flask\templating.py", line 89, in _get_source_fast
    raise TemplateNotFound(template)
jinja2.exceptions.TemplateNotFound: error/404.html

[2020-06-21 21:07:39,080 ERROR] [in E:\GitWorkplace\hting\application.py:46]
Traceback (most recent call last):
  File "E:\python\venv\hting\lib\site-packages\flask\app.py", line 1950, in full_dispatch_request
    rv = self.dispatch_request()
  File "E:\python\venv\hting\lib\site-packages\flask\app.py", line 1926, in dispatch_request
    self.raise_routing_exception(req)
  File "E:\python\venv\hting\lib\site-packages\flask\app.py", line 1908, in raise_routing_exception
    raise request.routing_exception
  File "E:\python\venv\hting\lib\site-packages\flask\ctx.py", line 350, in match_request
    result = self.url_adapter.match(return_rule=True)
  File "E:\python\venv\hting\lib\site-packages\werkzeug\routing.py", line 1945, in match
    raise NotFound()
werkzeug.exceptions.NotFound: 404 Not Found: The requested URL was not found on the server. If you entered the URL manually please check your spelling and try again.

During handling of the above exception, another exception occurred:

Traceback (most recent call last):
  File "E:\python\venv\hting\lib\site-packages\flask\app.py", line 2447, in wsgi_app
    response = self.full_dispatch_request()
  File "E:\python\venv\hting\lib\site-packages\flask\app.py", line 1952, in full_dispatch_request
    rv = self.handle_user_exception(e)
  File "E:\python\venv\hting\lib\site-packages\flask\app.py", line 1816, in handle_user_exception
    return self.handle_http_exception(e)
  File "E:\python\venv\hting\lib\site-packages\flask\app.py", line 1744, in handle_http_exception
    return handler(e)
  File "E:\GitWorkplace\hting\application.py", line 31, in page_not_found
    return render_template("error/404.html"), 404
  File "E:\python\venv\hting\lib\site-packages\flask\templating.py", line 138, in render_template
    ctx.app.jinja_env.get_or_select_template(template_name_or_list),
  File "E:\python\venv\hting\lib\site-packages\jinja2\environment.py", line 930, in get_or_select_template
    return self.get_template(template_name_or_list, parent, globals)
  File "E:\python\venv\hting\lib\site-packages\jinja2\environment.py", line 883, in get_template
    return self._load_template(name, self.make_globals(globals))
  File "E:\python\venv\hting\lib\site-packages\jinja2\environment.py", line 857, in _load_template
    template = self.loader.load(self, name, globals)
  File "E:\python\venv\hting\lib\site-packages\jinja2\loaders.py", line 115, in load
    source, filename, uptodate = self.get_source(environment, name)
  File "E:\python\venv\hting\lib\site-packages\flask\templating.py", line 60, in get_source
    return self._get_source_fast(environment, template)
  File "E:\python\venv\hting\lib\site-packages\flask\templating.py", line 89, in _get_source_fast
    raise TemplateNotFound(template)
jinja2.exceptions.TemplateNotFound: error/404.html

[2020-06-21 21:07:39,114 INFO] [in E:\python\venv\hting\lib\site-packages\werkzeug\_internal.py:113]
127.0.0.1 - - [21/Jun/2020 21:07:39] "[35m[1mGET /favicon.ico HTTP/1.1[0m" 500 -
[2020-06-21 21:07:39,132 ERROR] [in E:\python\venv\hting\lib\site-packages\werkzeug\_internal.py:113]
Error on request:
Traceback (most recent call last):
  File "E:\python\venv\hting\Lib\site-packages\flask\app.py", line 1950, in full_dispatch_request
    rv = self.dispatch_request()
  File "E:\python\venv\hting\Lib\site-packages\flask\app.py", line 1926, in dispatch_request
    self.raise_routing_exception(req)
  File "E:\python\venv\hting\Lib\site-packages\flask\app.py", line 1908, in raise_routing_exception
    raise request.routing_exception
  File "E:\python\venv\hting\Lib\site-packages\flask\ctx.py", line 350, in match_request
    result = self.url_adapter.match(return_rule=True)
  File "E:\python\venv\hting\Lib\site-packages\werkzeug\routing.py", line 1945, in match
    raise NotFound()
werkzeug.exceptions.NotFound: 404 Not Found: The requested URL was not found on the server. If you entered the URL manually please check your spelling and try again.

During handling of the above exception, another exception occurred:

Traceback (most recent call last):
  File "E:\python\venv\hting\Lib\site-packages\flask\app.py", line 2447, in wsgi_app
    response = self.full_dispatch_request()
  File "E:\python\venv\hting\Lib\site-packages\flask\app.py", line 1952, in full_dispatch_request
    rv = self.handle_user_exception(e)
  File "E:\python\venv\hting\Lib\site-packages\flask\app.py", line 1816, in handle_user_exception
    return self.handle_http_exception(e)
  File "E:\python\venv\hting\Lib\site-packages\flask\app.py", line 1744, in handle_http_exception
    return handler(e)
  File "E:\GitWorkplace\hting\application.py", line 31, in page_not_found
    return render_template("error/404.html"), 404
  File "E:\python\venv\hting\Lib\site-packages\flask\templating.py", line 138, in render_template
    ctx.app.jinja_env.get_or_select_template(template_name_or_list),
  File "E:\python\venv\hting\Lib\site-packages\jinja2\environment.py", line 930, in get_or_select_template
    return self.get_template(template_name_or_list, parent, globals)
  File "E:\python\venv\hting\Lib\site-packages\jinja2\environment.py", line 883, in get_template
    return self._load_template(name, self.make_globals(globals))
  File "E:\python\venv\hting\Lib\site-packages\jinja2\environment.py", line 857, in _load_template
    template = self.loader.load(self, name, globals)
  File "E:\python\venv\hting\Lib\site-packages\jinja2\loaders.py", line 115, in load
    source, filename, uptodate = self.get_source(environment, name)
  File "E:\python\venv\hting\Lib\site-packages\flask\templating.py", line 60, in get_source
    return self._get_source_fast(environment, template)
  File "E:\python\venv\hting\Lib\site-packages\flask\templating.py", line 89, in _get_source_fast
    raise TemplateNotFound(template)
jinja2.exceptions.TemplateNotFound: error/404.html

During handling of the above exception, another exception occurred:

Traceback (most recent call last):
  File "E:\python\venv\hting\Lib\site-packages\werkzeug\serving.py", line 323, in run_wsgi
    execute(self.server.app)
  File "E:\python\venv\hting\Lib\site-packages\werkzeug\serving.py", line 312, in execute
    application_iter = app(environ, start_response)
  File "E:\python\venv\hting\Lib\site-packages\flask\app.py", line 2464, in __call__
    return self.wsgi_app(environ, start_response)
  File "E:\python\venv\hting\Lib\site-packages\flask\app.py", line 2450, in wsgi_app
    response = self.handle_exception(e)
  File "E:\python\venv\hting\Lib\site-packages\flask\app.py", line 1879, in handle_exception
    server_error = handler(server_error)
  File "E:\GitWorkplace\hting\application.py", line 47, in error_handler
    return render_template("error/503.html"), code
  File "E:\python\venv\hting\Lib\site-packages\flask\templating.py", line 138, in render_template
    ctx.app.jinja_env.get_or_select_template(template_name_or_list),
  File "E:\python\venv\hting\Lib\site-packages\jinja2\environment.py", line 930, in get_or_select_template
    return self.get_template(template_name_or_list, parent, globals)
  File "E:\python\venv\hting\Lib\site-packages\jinja2\environment.py", line 883, in get_template
    return self._load_template(name, self.make_globals(globals))
  File "E:\python\venv\hting\Lib\site-packages\jinja2\environment.py", line 857, in _load_template
    template = self.loader.load(self, name, globals)
  File "E:\python\venv\hting\Lib\site-packages\jinja2\loaders.py", line 115, in load
    source, filename, uptodate = self.get_source(environment, name)
  File "E:\python\venv\hting\Lib\site-packages\flask\templating.py", line 60, in get_source
    return self._get_source_fast(environment, template)
  File "E:\python\venv\hting\Lib\site-packages\flask\templating.py", line 89, in _get_source_fast
    raise TemplateNotFound(template)
jinja2.exceptions.TemplateNotFound: error/503.html
[2020-06-21 21:08:02,065 ERROR] [in E:\python\venv\hting\lib\site-packages\flask\app.py:1891]
Exception on /test/test0 [GET]
Traceback (most recent call last):
  File "E:\python\venv\hting\lib\site-packages\flask\app.py", line 1950, in full_dispatch_request
    rv = self.dispatch_request()
  File "E:\python\venv\hting\lib\site-packages\flask\app.py", line 1926, in dispatch_request
    self.raise_routing_exception(req)
  File "E:\python\venv\hting\lib\site-packages\flask\app.py", line 1908, in raise_routing_exception
    raise request.routing_exception
  File "E:\python\venv\hting\lib\site-packages\flask\ctx.py", line 350, in match_request
    result = self.url_adapter.match(return_rule=True)
  File "E:\python\venv\hting\lib\site-packages\werkzeug\routing.py", line 1945, in match
    raise NotFound()
werkzeug.exceptions.NotFound: 404 Not Found: The requested URL was not found on the server. If you entered the URL manually please check your spelling and try again.

During handling of the above exception, another exception occurred:

Traceback (most recent call last):
  File "E:\python\venv\hting\lib\site-packages\flask\app.py", line 2447, in wsgi_app
    response = self.full_dispatch_request()
  File "E:\python\venv\hting\lib\site-packages\flask\app.py", line 1952, in full_dispatch_request
    rv = self.handle_user_exception(e)
  File "E:\python\venv\hting\lib\site-packages\flask\app.py", line 1816, in handle_user_exception
    return self.handle_http_exception(e)
  File "E:\python\venv\hting\lib\site-packages\flask\app.py", line 1744, in handle_http_exception
    return handler(e)
  File "E:\GitWorkplace\hting\application.py", line 31, in page_not_found
    return render_template("error/404.html"), 404
  File "E:\python\venv\hting\lib\site-packages\flask\templating.py", line 138, in render_template
    ctx.app.jinja_env.get_or_select_template(template_name_or_list),
  File "E:\python\venv\hting\lib\site-packages\jinja2\environment.py", line 930, in get_or_select_template
    return self.get_template(template_name_or_list, parent, globals)
  File "E:\python\venv\hting\lib\site-packages\jinja2\environment.py", line 883, in get_template
    return self._load_template(name, self.make_globals(globals))
  File "E:\python\venv\hting\lib\site-packages\jinja2\environment.py", line 857, in _load_template
    template = self.loader.load(self, name, globals)
  File "E:\python\venv\hting\lib\site-packages\jinja2\loaders.py", line 115, in load
    source, filename, uptodate = self.get_source(environment, name)
  File "E:\python\venv\hting\lib\site-packages\flask\templating.py", line 60, in get_source
    return self._get_source_fast(environment, template)
  File "E:\python\venv\hting\lib\site-packages\flask\templating.py", line 89, in _get_source_fast
    raise TemplateNotFound(template)
jinja2.exceptions.TemplateNotFound: error/404.html
[2020-06-21 21:08:02,065 ERROR] [in E:\python\venv\hting\lib\site-packages\flask\app.py:1891]
Exception on /test/test0 [GET]
Traceback (most recent call last):
  File "E:\python\venv\hting\lib\site-packages\flask\app.py", line 1950, in full_dispatch_request
    rv = self.dispatch_request()
  File "E:\python\venv\hting\lib\site-packages\flask\app.py", line 1926, in dispatch_request
    self.raise_routing_exception(req)
  File "E:\python\venv\hting\lib\site-packages\flask\app.py", line 1908, in raise_routing_exception
    raise request.routing_exception
  File "E:\python\venv\hting\lib\site-packages\flask\ctx.py", line 350, in match_request
    result = self.url_adapter.match(return_rule=True)
  File "E:\python\venv\hting\lib\site-packages\werkzeug\routing.py", line 1945, in match
    raise NotFound()
werkzeug.exceptions.NotFound: 404 Not Found: The requested URL was not found on the server. If you entered the URL manually please check your spelling and try again.

During handling of the above exception, another exception occurred:

Traceback (most recent call last):
  File "E:\python\venv\hting\lib\site-packages\flask\app.py", line 2447, in wsgi_app
    response = self.full_dispatch_request()
  File "E:\python\venv\hting\lib\site-packages\flask\app.py", line 1952, in full_dispatch_request
    rv = self.handle_user_exception(e)
  File "E:\python\venv\hting\lib\site-packages\flask\app.py", line 1816, in handle_user_exception
    return self.handle_http_exception(e)
  File "E:\python\venv\hting\lib\site-packages\flask\app.py", line 1744, in handle_http_exception
    return handler(e)
  File "E:\GitWorkplace\hting\application.py", line 31, in page_not_found
    return render_template("error/404.html"), 404
  File "E:\python\venv\hting\lib\site-packages\flask\templating.py", line 138, in render_template
    ctx.app.jinja_env.get_or_select_template(template_name_or_list),
  File "E:\python\venv\hting\lib\site-packages\jinja2\environment.py", line 930, in get_or_select_template
    return self.get_template(template_name_or_list, parent, globals)
  File "E:\python\venv\hting\lib\site-packages\jinja2\environment.py", line 883, in get_template
    return self._load_template(name, self.make_globals(globals))
  File "E:\python\venv\hting\lib\site-packages\jinja2\environment.py", line 857, in _load_template
    template = self.loader.load(self, name, globals)
  File "E:\python\venv\hting\lib\site-packages\jinja2\loaders.py", line 115, in load
    source, filename, uptodate = self.get_source(environment, name)
  File "E:\python\venv\hting\lib\site-packages\flask\templating.py", line 60, in get_source
    return self._get_source_fast(environment, template)
  File "E:\python\venv\hting\lib\site-packages\flask\templating.py", line 89, in _get_source_fast
    raise TemplateNotFound(template)
jinja2.exceptions.TemplateNotFound: error/404.html
[2020-06-21 21:08:02,072 ERROR] [in E:\GitWorkplace\hting\application.py:46]
Traceback (most recent call last):
  File "E:\python\venv\hting\lib\site-packages\flask\app.py", line 1950, in full_dispatch_request
    rv = self.dispatch_request()
  File "E:\python\venv\hting\lib\site-packages\flask\app.py", line 1926, in dispatch_request
    self.raise_routing_exception(req)
  File "E:\python\venv\hting\lib\site-packages\flask\app.py", line 1908, in raise_routing_exception
    raise request.routing_exception
  File "E:\python\venv\hting\lib\site-packages\flask\ctx.py", line 350, in match_request
    result = self.url_adapter.match(return_rule=True)
  File "E:\python\venv\hting\lib\site-packages\werkzeug\routing.py", line 1945, in match
    raise NotFound()
werkzeug.exceptions.NotFound: 404 Not Found: The requested URL was not found on the server. If you entered the URL manually please check your spelling and try again.

During handling of the above exception, another exception occurred:

Traceback (most recent call last):
  File "E:\python\venv\hting\lib\site-packages\flask\app.py", line 2447, in wsgi_app
    response = self.full_dispatch_request()
  File "E:\python\venv\hting\lib\site-packages\flask\app.py", line 1952, in full_dispatch_request
    rv = self.handle_user_exception(e)
  File "E:\python\venv\hting\lib\site-packages\flask\app.py", line 1816, in handle_user_exception
    return self.handle_http_exception(e)
  File "E:\python\venv\hting\lib\site-packages\flask\app.py", line 1744, in handle_http_exception
    return handler(e)
  File "E:\GitWorkplace\hting\application.py", line 31, in page_not_found
    return render_template("error/404.html"), 404
  File "E:\python\venv\hting\lib\site-packages\flask\templating.py", line 138, in render_template
    ctx.app.jinja_env.get_or_select_template(template_name_or_list),
  File "E:\python\venv\hting\lib\site-packages\jinja2\environment.py", line 930, in get_or_select_template
    return self.get_template(template_name_or_list, parent, globals)
  File "E:\python\venv\hting\lib\site-packages\jinja2\environment.py", line 883, in get_template
    return self._load_template(name, self.make_globals(globals))
  File "E:\python\venv\hting\lib\site-packages\jinja2\environment.py", line 857, in _load_template
    template = self.loader.load(self, name, globals)
  File "E:\python\venv\hting\lib\site-packages\jinja2\loaders.py", line 115, in load
    source, filename, uptodate = self.get_source(environment, name)
  File "E:\python\venv\hting\lib\site-packages\flask\templating.py", line 60, in get_source
    return self._get_source_fast(environment, template)
  File "E:\python\venv\hting\lib\site-packages\flask\templating.py", line 89, in _get_source_fast
    raise TemplateNotFound(template)
jinja2.exceptions.TemplateNotFound: error/404.html

[2020-06-21 21:08:02,072 ERROR] [in E:\GitWorkplace\hting\application.py:46]
Traceback (most recent call last):
  File "E:\python\venv\hting\lib\site-packages\flask\app.py", line 1950, in full_dispatch_request
    rv = self.dispatch_request()
  File "E:\python\venv\hting\lib\site-packages\flask\app.py", line 1926, in dispatch_request
    self.raise_routing_exception(req)
  File "E:\python\venv\hting\lib\site-packages\flask\app.py", line 1908, in raise_routing_exception
    raise request.routing_exception
  File "E:\python\venv\hting\lib\site-packages\flask\ctx.py", line 350, in match_request
    result = self.url_adapter.match(return_rule=True)
  File "E:\python\venv\hting\lib\site-packages\werkzeug\routing.py", line 1945, in match
    raise NotFound()
werkzeug.exceptions.NotFound: 404 Not Found: The requested URL was not found on the server. If you entered the URL manually please check your spelling and try again.

During handling of the above exception, another exception occurred:

Traceback (most recent call last):
  File "E:\python\venv\hting\lib\site-packages\flask\app.py", line 2447, in wsgi_app
    response = self.full_dispatch_request()
  File "E:\python\venv\hting\lib\site-packages\flask\app.py", line 1952, in full_dispatch_request
    rv = self.handle_user_exception(e)
  File "E:\python\venv\hting\lib\site-packages\flask\app.py", line 1816, in handle_user_exception
    return self.handle_http_exception(e)
  File "E:\python\venv\hting\lib\site-packages\flask\app.py", line 1744, in handle_http_exception
    return handler(e)
  File "E:\GitWorkplace\hting\application.py", line 31, in page_not_found
    return render_template("error/404.html"), 404
  File "E:\python\venv\hting\lib\site-packages\flask\templating.py", line 138, in render_template
    ctx.app.jinja_env.get_or_select_template(template_name_or_list),
  File "E:\python\venv\hting\lib\site-packages\jinja2\environment.py", line 930, in get_or_select_template
    return self.get_template(template_name_or_list, parent, globals)
  File "E:\python\venv\hting\lib\site-packages\jinja2\environment.py", line 883, in get_template
    return self._load_template(name, self.make_globals(globals))
  File "E:\python\venv\hting\lib\site-packages\jinja2\environment.py", line 857, in _load_template
    template = self.loader.load(self, name, globals)
  File "E:\python\venv\hting\lib\site-packages\jinja2\loaders.py", line 115, in load
    source, filename, uptodate = self.get_source(environment, name)
  File "E:\python\venv\hting\lib\site-packages\flask\templating.py", line 60, in get_source
    return self._get_source_fast(environment, template)
  File "E:\python\venv\hting\lib\site-packages\flask\templating.py", line 89, in _get_source_fast
    raise TemplateNotFound(template)
jinja2.exceptions.TemplateNotFound: error/404.html

[2020-06-21 21:08:02,099 INFO] [in E:\python\venv\hting\lib\site-packages\werkzeug\_internal.py:113]
127.0.0.1 - - [21/Jun/2020 21:08:02] "[35m[1mGET /test/test0 HTTP/1.1[0m" 500 -
[2020-06-21 21:08:02,119 ERROR] [in E:\python\venv\hting\lib\site-packages\flask\app.py:1891]
Exception on /favicon.ico [GET]
Traceback (most recent call last):
  File "E:\python\venv\hting\lib\site-packages\flask\app.py", line 1950, in full_dispatch_request
    rv = self.dispatch_request()
  File "E:\python\venv\hting\lib\site-packages\flask\app.py", line 1926, in dispatch_request
    self.raise_routing_exception(req)
  File "E:\python\venv\hting\lib\site-packages\flask\app.py", line 1908, in raise_routing_exception
    raise request.routing_exception
  File "E:\python\venv\hting\lib\site-packages\flask\ctx.py", line 350, in match_request
    result = self.url_adapter.match(return_rule=True)
  File "E:\python\venv\hting\lib\site-packages\werkzeug\routing.py", line 1945, in match
    raise NotFound()
werkzeug.exceptions.NotFound: 404 Not Found: The requested URL was not found on the server. If you entered the URL manually please check your spelling and try again.

During handling of the above exception, another exception occurred:

Traceback (most recent call last):
  File "E:\python\venv\hting\lib\site-packages\flask\app.py", line 2447, in wsgi_app
    response = self.full_dispatch_request()
  File "E:\python\venv\hting\lib\site-packages\flask\app.py", line 1952, in full_dispatch_request
    rv = self.handle_user_exception(e)
  File "E:\python\venv\hting\lib\site-packages\flask\app.py", line 1816, in handle_user_exception
    return self.handle_http_exception(e)
  File "E:\python\venv\hting\lib\site-packages\flask\app.py", line 1744, in handle_http_exception
    return handler(e)
  File "E:\GitWorkplace\hting\application.py", line 31, in page_not_found
    return render_template("error/404.html"), 404
  File "E:\python\venv\hting\lib\site-packages\flask\templating.py", line 138, in render_template
    ctx.app.jinja_env.get_or_select_template(template_name_or_list),
  File "E:\python\venv\hting\lib\site-packages\jinja2\environment.py", line 930, in get_or_select_template
    return self.get_template(template_name_or_list, parent, globals)
  File "E:\python\venv\hting\lib\site-packages\jinja2\environment.py", line 883, in get_template
    return self._load_template(name, self.make_globals(globals))
  File "E:\python\venv\hting\lib\site-packages\jinja2\environment.py", line 857, in _load_template
    template = self.loader.load(self, name, globals)
  File "E:\python\venv\hting\lib\site-packages\jinja2\loaders.py", line 115, in load
    source, filename, uptodate = self.get_source(environment, name)
  File "E:\python\venv\hting\lib\site-packages\flask\templating.py", line 60, in get_source
    return self._get_source_fast(environment, template)
  File "E:\python\venv\hting\lib\site-packages\flask\templating.py", line 89, in _get_source_fast
    raise TemplateNotFound(template)
jinja2.exceptions.TemplateNotFound: error/404.html
[2020-06-21 21:08:02,119 ERROR] [in E:\python\venv\hting\lib\site-packages\flask\app.py:1891]
Exception on /favicon.ico [GET]
Traceback (most recent call last):
  File "E:\python\venv\hting\lib\site-packages\flask\app.py", line 1950, in full_dispatch_request
    rv = self.dispatch_request()
  File "E:\python\venv\hting\lib\site-packages\flask\app.py", line 1926, in dispatch_request
    self.raise_routing_exception(req)
  File "E:\python\venv\hting\lib\site-packages\flask\app.py", line 1908, in raise_routing_exception
    raise request.routing_exception
  File "E:\python\venv\hting\lib\site-packages\flask\ctx.py", line 350, in match_request
    result = self.url_adapter.match(return_rule=True)
  File "E:\python\venv\hting\lib\site-packages\werkzeug\routing.py", line 1945, in match
    raise NotFound()
werkzeug.exceptions.NotFound: 404 Not Found: The requested URL was not found on the server. If you entered the URL manually please check your spelling and try again.

During handling of the above exception, another exception occurred:

Traceback (most recent call last):
  File "E:\python\venv\hting\lib\site-packages\flask\app.py", line 2447, in wsgi_app
    response = self.full_dispatch_request()
  File "E:\python\venv\hting\lib\site-packages\flask\app.py", line 1952, in full_dispatch_request
    rv = self.handle_user_exception(e)
  File "E:\python\venv\hting\lib\site-packages\flask\app.py", line 1816, in handle_user_exception
    return self.handle_http_exception(e)
  File "E:\python\venv\hting\lib\site-packages\flask\app.py", line 1744, in handle_http_exception
    return handler(e)
  File "E:\GitWorkplace\hting\application.py", line 31, in page_not_found
    return render_template("error/404.html"), 404
  File "E:\python\venv\hting\lib\site-packages\flask\templating.py", line 138, in render_template
    ctx.app.jinja_env.get_or_select_template(template_name_or_list),
  File "E:\python\venv\hting\lib\site-packages\jinja2\environment.py", line 930, in get_or_select_template
    return self.get_template(template_name_or_list, parent, globals)
  File "E:\python\venv\hting\lib\site-packages\jinja2\environment.py", line 883, in get_template
    return self._load_template(name, self.make_globals(globals))
  File "E:\python\venv\hting\lib\site-packages\jinja2\environment.py", line 857, in _load_template
    template = self.loader.load(self, name, globals)
  File "E:\python\venv\hting\lib\site-packages\jinja2\loaders.py", line 115, in load
    source, filename, uptodate = self.get_source(environment, name)
  File "E:\python\venv\hting\lib\site-packages\flask\templating.py", line 60, in get_source
    return self._get_source_fast(environment, template)
  File "E:\python\venv\hting\lib\site-packages\flask\templating.py", line 89, in _get_source_fast
    raise TemplateNotFound(template)
jinja2.exceptions.TemplateNotFound: error/404.html
[2020-06-21 21:08:02,128 ERROR] [in E:\GitWorkplace\hting\application.py:46]
Traceback (most recent call last):
  File "E:\python\venv\hting\lib\site-packages\flask\app.py", line 1950, in full_dispatch_request
    rv = self.dispatch_request()
  File "E:\python\venv\hting\lib\site-packages\flask\app.py", line 1926, in dispatch_request
    self.raise_routing_exception(req)
  File "E:\python\venv\hting\lib\site-packages\flask\app.py", line 1908, in raise_routing_exception
    raise request.routing_exception
  File "E:\python\venv\hting\lib\site-packages\flask\ctx.py", line 350, in match_request
    result = self.url_adapter.match(return_rule=True)
  File "E:\python\venv\hting\lib\site-packages\werkzeug\routing.py", line 1945, in match
    raise NotFound()
werkzeug.exceptions.NotFound: 404 Not Found: The requested URL was not found on the server. If you entered the URL manually please check your spelling and try again.

During handling of the above exception, another exception occurred:

Traceback (most recent call last):
  File "E:\python\venv\hting\lib\site-packages\flask\app.py", line 2447, in wsgi_app
    response = self.full_dispatch_request()
  File "E:\python\venv\hting\lib\site-packages\flask\app.py", line 1952, in full_dispatch_request
    rv = self.handle_user_exception(e)
  File "E:\python\venv\hting\lib\site-packages\flask\app.py", line 1816, in handle_user_exception
    return self.handle_http_exception(e)
  File "E:\python\venv\hting\lib\site-packages\flask\app.py", line 1744, in handle_http_exception
    return handler(e)
  File "E:\GitWorkplace\hting\application.py", line 31, in page_not_found
    return render_template("error/404.html"), 404
  File "E:\python\venv\hting\lib\site-packages\flask\templating.py", line 138, in render_template
    ctx.app.jinja_env.get_or_select_template(template_name_or_list),
  File "E:\python\venv\hting\lib\site-packages\jinja2\environment.py", line 930, in get_or_select_template
    return self.get_template(template_name_or_list, parent, globals)
  File "E:\python\venv\hting\lib\site-packages\jinja2\environment.py", line 883, in get_template
    return self._load_template(name, self.make_globals(globals))
  File "E:\python\venv\hting\lib\site-packages\jinja2\environment.py", line 857, in _load_template
    template = self.loader.load(self, name, globals)
  File "E:\python\venv\hting\lib\site-packages\jinja2\loaders.py", line 115, in load
    source, filename, uptodate = self.get_source(environment, name)
  File "E:\python\venv\hting\lib\site-packages\flask\templating.py", line 60, in get_source
    return self._get_source_fast(environment, template)
  File "E:\python\venv\hting\lib\site-packages\flask\templating.py", line 89, in _get_source_fast
    raise TemplateNotFound(template)
jinja2.exceptions.TemplateNotFound: error/404.html

[2020-06-21 21:08:02,128 ERROR] [in E:\GitWorkplace\hting\application.py:46]
Traceback (most recent call last):
  File "E:\python\venv\hting\lib\site-packages\flask\app.py", line 1950, in full_dispatch_request
    rv = self.dispatch_request()
  File "E:\python\venv\hting\lib\site-packages\flask\app.py", line 1926, in dispatch_request
    self.raise_routing_exception(req)
  File "E:\python\venv\hting\lib\site-packages\flask\app.py", line 1908, in raise_routing_exception
    raise request.routing_exception
  File "E:\python\venv\hting\lib\site-packages\flask\ctx.py", line 350, in match_request
    result = self.url_adapter.match(return_rule=True)
  File "E:\python\venv\hting\lib\site-packages\werkzeug\routing.py", line 1945, in match
    raise NotFound()
werkzeug.exceptions.NotFound: 404 Not Found: The requested URL was not found on the server. If you entered the URL manually please check your spelling and try again.

During handling of the above exception, another exception occurred:

Traceback (most recent call last):
  File "E:\python\venv\hting\lib\site-packages\flask\app.py", line 2447, in wsgi_app
    response = self.full_dispatch_request()
  File "E:\python\venv\hting\lib\site-packages\flask\app.py", line 1952, in full_dispatch_request
    rv = self.handle_user_exception(e)
  File "E:\python\venv\hting\lib\site-packages\flask\app.py", line 1816, in handle_user_exception
    return self.handle_http_exception(e)
  File "E:\python\venv\hting\lib\site-packages\flask\app.py", line 1744, in handle_http_exception
    return handler(e)
  File "E:\GitWorkplace\hting\application.py", line 31, in page_not_found
    return render_template("error/404.html"), 404
  File "E:\python\venv\hting\lib\site-packages\flask\templating.py", line 138, in render_template
    ctx.app.jinja_env.get_or_select_template(template_name_or_list),
  File "E:\python\venv\hting\lib\site-packages\jinja2\environment.py", line 930, in get_or_select_template
    return self.get_template(template_name_or_list, parent, globals)
  File "E:\python\venv\hting\lib\site-packages\jinja2\environment.py", line 883, in get_template
    return self._load_template(name, self.make_globals(globals))
  File "E:\python\venv\hting\lib\site-packages\jinja2\environment.py", line 857, in _load_template
    template = self.loader.load(self, name, globals)
  File "E:\python\venv\hting\lib\site-packages\jinja2\loaders.py", line 115, in load
    source, filename, uptodate = self.get_source(environment, name)
  File "E:\python\venv\hting\lib\site-packages\flask\templating.py", line 60, in get_source
    return self._get_source_fast(environment, template)
  File "E:\python\venv\hting\lib\site-packages\flask\templating.py", line 89, in _get_source_fast
    raise TemplateNotFound(template)
jinja2.exceptions.TemplateNotFound: error/404.html

[2020-06-21 21:08:02,129 ERROR] [in E:\python\venv\hting\lib\site-packages\werkzeug\_internal.py:113]
Error on request:
Traceback (most recent call last):
  File "E:\python\venv\hting\Lib\site-packages\flask\app.py", line 1950, in full_dispatch_request
    rv = self.dispatch_request()
  File "E:\python\venv\hting\Lib\site-packages\flask\app.py", line 1926, in dispatch_request
    self.raise_routing_exception(req)
  File "E:\python\venv\hting\Lib\site-packages\flask\app.py", line 1908, in raise_routing_exception
    raise request.routing_exception
  File "E:\python\venv\hting\Lib\site-packages\flask\ctx.py", line 350, in match_request
    result = self.url_adapter.match(return_rule=True)
  File "E:\python\venv\hting\Lib\site-packages\werkzeug\routing.py", line 1945, in match
    raise NotFound()
werkzeug.exceptions.NotFound: 404 Not Found: The requested URL was not found on the server. If you entered the URL manually please check your spelling and try again.

During handling of the above exception, another exception occurred:

Traceback (most recent call last):
  File "E:\python\venv\hting\Lib\site-packages\flask\app.py", line 2447, in wsgi_app
    response = self.full_dispatch_request()
  File "E:\python\venv\hting\Lib\site-packages\flask\app.py", line 1952, in full_dispatch_request
    rv = self.handle_user_exception(e)
  File "E:\python\venv\hting\Lib\site-packages\flask\app.py", line 1816, in handle_user_exception
    return self.handle_http_exception(e)
  File "E:\python\venv\hting\Lib\site-packages\flask\app.py", line 1744, in handle_http_exception
    return handler(e)
  File "E:\GitWorkplace\hting\application.py", line 31, in page_not_found
    return render_template("error/404.html"), 404
  File "E:\python\venv\hting\Lib\site-packages\flask\templating.py", line 138, in render_template
    ctx.app.jinja_env.get_or_select_template(template_name_or_list),
  File "E:\python\venv\hting\Lib\site-packages\jinja2\environment.py", line 930, in get_or_select_template
    return self.get_template(template_name_or_list, parent, globals)
  File "E:\python\venv\hting\Lib\site-packages\jinja2\environment.py", line 883, in get_template
    return self._load_template(name, self.make_globals(globals))
  File "E:\python\venv\hting\Lib\site-packages\jinja2\environment.py", line 857, in _load_template
    template = self.loader.load(self, name, globals)
  File "E:\python\venv\hting\Lib\site-packages\jinja2\loaders.py", line 115, in load
    source, filename, uptodate = self.get_source(environment, name)
  File "E:\python\venv\hting\Lib\site-packages\flask\templating.py", line 60, in get_source
    return self._get_source_fast(environment, template)
  File "E:\python\venv\hting\Lib\site-packages\flask\templating.py", line 89, in _get_source_fast
    raise TemplateNotFound(template)
jinja2.exceptions.TemplateNotFound: error/404.html

During handling of the above exception, another exception occurred:

Traceback (most recent call last):
  File "E:\python\venv\hting\Lib\site-packages\werkzeug\serving.py", line 323, in run_wsgi
    execute(self.server.app)
  File "E:\python\venv\hting\Lib\site-packages\werkzeug\serving.py", line 312, in execute
    application_iter = app(environ, start_response)
  File "E:\python\venv\hting\Lib\site-packages\flask\app.py", line 2464, in __call__
    return self.wsgi_app(environ, start_response)
  File "E:\python\venv\hting\Lib\site-packages\flask\app.py", line 2450, in wsgi_app
    response = self.handle_exception(e)
  File "E:\python\venv\hting\Lib\site-packages\flask\app.py", line 1879, in handle_exception
    server_error = handler(server_error)
  File "E:\GitWorkplace\hting\application.py", line 47, in error_handler
    return render_template("error/503.html"), code
  File "E:\python\venv\hting\Lib\site-packages\flask\templating.py", line 138, in render_template
    ctx.app.jinja_env.get_or_select_template(template_name_or_list),
  File "E:\python\venv\hting\Lib\site-packages\jinja2\environment.py", line 930, in get_or_select_template
    return self.get_template(template_name_or_list, parent, globals)
  File "E:\python\venv\hting\Lib\site-packages\jinja2\environment.py", line 883, in get_template
    return self._load_template(name, self.make_globals(globals))
  File "E:\python\venv\hting\Lib\site-packages\jinja2\environment.py", line 857, in _load_template
    template = self.loader.load(self, name, globals)
  File "E:\python\venv\hting\Lib\site-packages\jinja2\loaders.py", line 115, in load
    source, filename, uptodate = self.get_source(environment, name)
  File "E:\python\venv\hting\Lib\site-packages\flask\templating.py", line 60, in get_source
    return self._get_source_fast(environment, template)
  File "E:\python\venv\hting\Lib\site-packages\flask\templating.py", line 89, in _get_source_fast
    raise TemplateNotFound(template)
jinja2.exceptions.TemplateNotFound: error/503.html
[2020-06-21 21:08:02,155 INFO] [in E:\python\venv\hting\lib\site-packages\werkzeug\_internal.py:113]
127.0.0.1 - - [21/Jun/2020 21:08:02] "[35m[1mGET /favicon.ico HTTP/1.1[0m" 500 -
[2020-06-21 21:08:02,173 ERROR] [in E:\python\venv\hting\lib\site-packages\werkzeug\_internal.py:113]
Error on request:
Traceback (most recent call last):
  File "E:\python\venv\hting\Lib\site-packages\flask\app.py", line 1950, in full_dispatch_request
    rv = self.dispatch_request()
  File "E:\python\venv\hting\Lib\site-packages\flask\app.py", line 1926, in dispatch_request
    self.raise_routing_exception(req)
  File "E:\python\venv\hting\Lib\site-packages\flask\app.py", line 1908, in raise_routing_exception
    raise request.routing_exception
  File "E:\python\venv\hting\Lib\site-packages\flask\ctx.py", line 350, in match_request
    result = self.url_adapter.match(return_rule=True)
  File "E:\python\venv\hting\Lib\site-packages\werkzeug\routing.py", line 1945, in match
    raise NotFound()
werkzeug.exceptions.NotFound: 404 Not Found: The requested URL was not found on the server. If you entered the URL manually please check your spelling and try again.

During handling of the above exception, another exception occurred:

Traceback (most recent call last):
  File "E:\python\venv\hting\Lib\site-packages\flask\app.py", line 2447, in wsgi_app
    response = self.full_dispatch_request()
  File "E:\python\venv\hting\Lib\site-packages\flask\app.py", line 1952, in full_dispatch_request
    rv = self.handle_user_exception(e)
  File "E:\python\venv\hting\Lib\site-packages\flask\app.py", line 1816, in handle_user_exception
    return self.handle_http_exception(e)
  File "E:\python\venv\hting\Lib\site-packages\flask\app.py", line 1744, in handle_http_exception
    return handler(e)
  File "E:\GitWorkplace\hting\application.py", line 31, in page_not_found
    return render_template("error/404.html"), 404
  File "E:\python\venv\hting\Lib\site-packages\flask\templating.py", line 138, in render_template
    ctx.app.jinja_env.get_or_select_template(template_name_or_list),
  File "E:\python\venv\hting\Lib\site-packages\jinja2\environment.py", line 930, in get_or_select_template
    return self.get_template(template_name_or_list, parent, globals)
  File "E:\python\venv\hting\Lib\site-packages\jinja2\environment.py", line 883, in get_template
    return self._load_template(name, self.make_globals(globals))
  File "E:\python\venv\hting\Lib\site-packages\jinja2\environment.py", line 857, in _load_template
    template = self.loader.load(self, name, globals)
  File "E:\python\venv\hting\Lib\site-packages\jinja2\loaders.py", line 115, in load
    source, filename, uptodate = self.get_source(environment, name)
  File "E:\python\venv\hting\Lib\site-packages\flask\templating.py", line 60, in get_source
    return self._get_source_fast(environment, template)
  File "E:\python\venv\hting\Lib\site-packages\flask\templating.py", line 89, in _get_source_fast
    raise TemplateNotFound(template)
jinja2.exceptions.TemplateNotFound: error/404.html

During handling of the above exception, another exception occurred:

Traceback (most recent call last):
  File "E:\python\venv\hting\Lib\site-packages\werkzeug\serving.py", line 323, in run_wsgi
    execute(self.server.app)
  File "E:\python\venv\hting\Lib\site-packages\werkzeug\serving.py", line 312, in execute
    application_iter = app(environ, start_response)
  File "E:\python\venv\hting\Lib\site-packages\flask\app.py", line 2464, in __call__
    return self.wsgi_app(environ, start_response)
  File "E:\python\venv\hting\Lib\site-packages\flask\app.py", line 2450, in wsgi_app
    response = self.handle_exception(e)
  File "E:\python\venv\hting\Lib\site-packages\flask\app.py", line 1879, in handle_exception
    server_error = handler(server_error)
  File "E:\GitWorkplace\hting\application.py", line 47, in error_handler
    return render_template("error/503.html"), code
  File "E:\python\venv\hting\Lib\site-packages\flask\templating.py", line 138, in render_template
    ctx.app.jinja_env.get_or_select_template(template_name_or_list),
  File "E:\python\venv\hting\Lib\site-packages\jinja2\environment.py", line 930, in get_or_select_template
    return self.get_template(template_name_or_list, parent, globals)
  File "E:\python\venv\hting\Lib\site-packages\jinja2\environment.py", line 883, in get_template
    return self._load_template(name, self.make_globals(globals))
  File "E:\python\venv\hting\Lib\site-packages\jinja2\environment.py", line 857, in _load_template
    template = self.loader.load(self, name, globals)
  File "E:\python\venv\hting\Lib\site-packages\jinja2\loaders.py", line 115, in load
    source, filename, uptodate = self.get_source(environment, name)
  File "E:\python\venv\hting\Lib\site-packages\flask\templating.py", line 60, in get_source
    return self._get_source_fast(environment, template)
  File "E:\python\venv\hting\Lib\site-packages\flask\templating.py", line 89, in _get_source_fast
    raise TemplateNotFound(template)
jinja2.exceptions.TemplateNotFound: error/503.html
[2020-06-21 21:49:57,013 INFO] [in E:\GitWorkplace\hting\utils\loggings.py:77]
this is root_logger logging: app.logger is True, configuring app_logger.......
[2020-06-21 21:49:57,013 WARNING] [in E:\GitWorkplace\hting\application.py:24]
启动生产模式
[2020-06-21 21:49:57,013 WARNING] [in E:\GitWorkplace\hting\application.py:24]
启动生产模式
[2020-06-21 21:49:57,285 INFO] [in E:\python\venv\hting\lib\site-packages\werkzeug\_internal.py:113]
 * Running on http://127.0.0.1:5000/ (Press CTRL+C to quit)
[2020-06-21 21:50:07,199 INFO] [in E:\GitWorkplace\hting\src\api\bogtest.py:22]
this is in hello/get
[2020-06-21 21:50:07,201 INFO] [in E:\python\venv\hting\lib\site-packages\werkzeug\_internal.py:113]
127.0.0.1 - - [21/Jun/2020 21:50:07] "[37mGET /api/test/hello HTTP/1.1[0m" 200 -
